2022-11-14 13:38:20,290 :: INFO -- Watching for file changes with StatReloader
2022-11-14 13:38:56,926 :: ERROR -- Internal Server Error: /accounts/google/login/
Traceback (most recent call last):
  File "C:\Users\Alexandr\PycharmProjects\Reset001\venv\lib\site-packages\django\core\handlers\exception.py", line 55, in inner
    response = get_response(request)
  File "C:\Users\Alexandr\PycharmProjects\Reset001\venv\lib\site-packages\django\core\handlers\base.py", line 197, in _get_response
    response = wrapped_callback(request, *callback_args, **callback_kwargs)
  File "C:\Users\Alexandr\PycharmProjects\Reset001\venv\lib\site-packages\allauth\socialaccount\providers\oauth2\views.py", line 80, in view
    return self.dispatch(request, *args, **kwargs)
  File "C:\Users\Alexandr\PycharmProjects\Reset001\venv\lib\site-packages\allauth\socialaccount\providers\base\mixins.py", line 18, in dispatch
    return self.login(request, *args, **kwargs)
  File "C:\Users\Alexandr\PycharmProjects\Reset001\venv\lib\site-packages\allauth\socialaccount\providers\oauth2\views.py", line 108, in login
    app = provider.get_app(self.request)
  File "C:\Users\Alexandr\PycharmProjects\Reset001\venv\lib\site-packages\allauth\socialaccount\providers\base\provider.py", line 30, in get_app
    return adapter.get_app(request, self.id)
  File "C:\Users\Alexandr\PycharmProjects\Reset001\venv\lib\site-packages\allauth\socialaccount\adapter.py", line 204, in get_app
    app = SocialApp.objects.get_current(provider, request)
  File "C:\Users\Alexandr\PycharmProjects\Reset001\venv\lib\site-packages\allauth\socialaccount\models.py", line 31, in get_current
    app = self.get(sites__id=site.id, provider=provider)
  File "C:\Users\Alexandr\PycharmProjects\Reset001\venv\lib\site-packages\django\db\models\manager.py", line 85, in manager_method
    return getattr(self.get_queryset(), name)(*args, **kwargs)
  File "C:\Users\Alexandr\PycharmProjects\Reset001\venv\lib\site-packages\django\db\models\query.py", line 650, in get
    raise self.model.DoesNotExist(
allauth.socialaccount.models.SocialApp.DoesNotExist: SocialApp matching query does not exist.
2022-11-14 13:38:56,926 :: ERROR -- Internal Server Error: /accounts/google/login/
Traceback (most recent call last):
  File "C:\Users\Alexandr\PycharmProjects\Reset001\venv\lib\site-packages\django\core\handlers\exception.py", line 55, in inner
    response = get_response(request)
  File "C:\Users\Alexandr\PycharmProjects\Reset001\venv\lib\site-packages\django\core\handlers\base.py", line 197, in _get_response
    response = wrapped_callback(request, *callback_args, **callback_kwargs)
  File "C:\Users\Alexandr\PycharmProjects\Reset001\venv\lib\site-packages\allauth\socialaccount\providers\oauth2\views.py", line 80, in view
    return self.dispatch(request, *args, **kwargs)
  File "C:\Users\Alexandr\PycharmProjects\Reset001\venv\lib\site-packages\allauth\socialaccount\providers\base\mixins.py", line 18, in dispatch
    return self.login(request, *args, **kwargs)
  File "C:\Users\Alexandr\PycharmProjects\Reset001\venv\lib\site-packages\allauth\socialaccount\providers\oauth2\views.py", line 108, in login
    app = provider.get_app(self.request)
  File "C:\Users\Alexandr\PycharmProjects\Reset001\venv\lib\site-packages\allauth\socialaccount\providers\base\provider.py", line 30, in get_app
    return adapter.get_app(request, self.id)
  File "C:\Users\Alexandr\PycharmProjects\Reset001\venv\lib\site-packages\allauth\socialaccount\adapter.py", line 204, in get_app
    app = SocialApp.objects.get_current(provider, request)
  File "C:\Users\Alexandr\PycharmProjects\Reset001\venv\lib\site-packages\allauth\socialaccount\models.py", line 31, in get_current
    app = self.get(sites__id=site.id, provider=provider)
  File "C:\Users\Alexandr\PycharmProjects\Reset001\venv\lib\site-packages\django\db\models\manager.py", line 85, in manager_method
    return getattr(self.get_queryset(), name)(*args, **kwargs)
  File "C:\Users\Alexandr\PycharmProjects\Reset001\venv\lib\site-packages\django\db\models\query.py", line 650, in get
    raise self.model.DoesNotExist(
allauth.socialaccount.models.SocialApp.DoesNotExist: SocialApp matching query does not exist.
2022-11-14 13:38:58,058 :: ERROR -- "POST /accounts/google/login/?process=login&next=%2F HTTP/1.1" 500 145
2022-11-14 13:39:15,015 :: WARNING -- Not Found: /static/vendor/bootstrap/css/bootstrap.min.css
2022-11-14 13:39:15,015 :: WARNING -- Not Found: /static/vendor/bootstrap/css/bootstrap.min.css
2022-11-14 13:39:15,017 :: WARNING -- Not Found: /static/vendor/bootstrap/js/bootstrap.bundle.min.js
2022-11-14 13:39:15,017 :: WARNING -- Not Found: /static/vendor/bootstrap/js/bootstrap.bundle.min.js
2022-11-14 13:39:15,026 :: WARNING -- Not Found: /static/vendor/jquery/jquery.slim.min.js
2022-11-14 13:39:15,026 :: WARNING -- Not Found: /static/vendor/jquery/jquery.slim.min.js
2022-11-14 13:39:17,208 :: WARNING -- Not Found: /contacts/
2022-11-14 13:39:17,208 :: WARNING -- Not Found: /contacts/
2022-11-14 13:39:19,855 :: WARNING -- Not Found: /registration/
2022-11-14 13:39:19,855 :: WARNING -- Not Found: /registration/
2022-11-14 13:39:22,569 :: WARNING -- Not Found: /static/vendor/jquery/jquery.slim.min.js
2022-11-14 13:39:22,569 :: WARNING -- Not Found: /static/vendor/jquery/jquery.slim.min.js
2022-11-14 13:39:22,571 :: WARNING -- Not Found: /static/vendor/bootstrap/js/bootstrap.bundle.min.js
2022-11-14 13:39:22,571 :: WARNING -- Not Found: /static/vendor/bootstrap/js/bootstrap.bundle.min.js
2022-11-14 13:39:22,582 :: WARNING -- Not Found: /static/vendor/bootstrap/css/bootstrap.min.css
2022-11-14 13:39:22,582 :: WARNING -- Not Found: /static/vendor/bootstrap/css/bootstrap.min.css
2022-11-14 13:39:24,606 :: WARNING -- Not Found: /home/
2022-11-14 13:39:24,606 :: WARNING -- Not Found: /home/
2022-11-14 13:39:28,399 :: WARNING -- Not Found: /home/
2022-11-14 13:39:28,399 :: WARNING -- Not Found: /home/
2022-11-14 15:30:02,800 :: INFO -- Watching for file changes with StatReloader
